{"project_id":"sample-medieval-castle","preview":{"blocks":[{"x":0,"y":64,"z":0,"block":"minecraft:stone_bricks","region":"R1","texture":"textures/block/stone_bricks.png"},{"x":0,"y":64,"z":1,"block":"minecraft:stone_bricks","region":"R1","texture":"textures/block/stone_bricks.png"},{"x":0,"y":64,"z":2,"block":"minecraft:stone_bricks","region":"R1","texture":"textures/block/stone_bricks.png"},{"x":0,"y":64,"z":3,"block":"minecraft:stone_bricks","region":"R1","texture":"textures/block/stone_bricks.png"},{"x":0,"y":64,"z":4,"block":"minecraft:stone_bricks","region":"R1","texture":"textures/block/stone_bricks.png"},{"x":0,"y":64,"z":5,"block":"minecraft:stone_bricks","region":"R1","texture":"textures/block/stone_bricks.png"},{"x":0,"y":64,"z":6,"block":"minecraft:stone_bricks","region":"R3","texture":"textures/block/stone_bricks.png"},{"x":0,"y":64,"z":7,"block":"minecraft:stone_bricks","region":"R3","texture":"textures/block/stone_bricks.png"},{"x":0,"y":64,"z":8,"block":"minecraft:stone_bricks","region":"R3","texture":"textures/block/stone_bricks.png"},{"x":0,"y":64,"z":9,"block":"minecraft:stone_bricks","region":"R3","texture":"textures/block/stone_bricks.png"},{"x":0,"y":64,"z":10,"block":"minecraft:stone_bricks","region":"R3","texture":"textures/block/stone_bricks.png"},{"x":0,"y":64,"z":11,"block":"minecraft:stone_bricks","region":"R3","texture":"textures/block/stone_bricks.png"},{"x":0,"y":65,"z":0,"block":"minecraft:stone_bricks","region":"R1","texture":"textures/block/stone_bricks.png"},{"x":0,"y":65,"z":1,"block":"minecraft:stone_bricks","region":"R1","texture":"textures/block/stone_bricks.png"},{"x":0,"y":65,"z":2,"block":"minecraft:stone_bricks","region":"R1","texture":"textures/block/stone_bricks.png"},{"x":0,"y":65,"z":3,"block":"minecraft:stone_bricks","region":"R1","texture":"textures/block/stone_bricks.png"},{"x":0,"y":65,"z":4,"block":"minecraft:stone_bricks","region":"R1","texture":"textures/block/stone_bricks.png"},{"x":0,"y":65,"z":5,"block":"minecraft:stone_bricks","region":"R1","texture":"textures/block/stone_bricks.png"},{"x":0,"y":65,"z":6,"block":"minecraft:stone_bricks","region":"R3","texture":"textures/block/stone_bricks.png"},{"x":0,"y":65,"z":7,"block":"minecraft:stone_bricks","region":"R3","texture":"textures/block/stone_bricks.png"},{"x":0,"y":65,"z":8,"block":"minecraft:stone_bricks","region":"R3","texture":"textures/block/stone_bricks.png"},{"x":0,"y":65,"z":9,"block":"minecraft:stone_bricks","region":"R3","texture":"textures/block/stone_bricks.png"},{"x":0,"y":65,"z":10,"block":"minecraft:stone_bricks","region":"R3","texture":"textures/block/stone_bricks.png"},{"x":0,"y":65,"z":11,"block":"minecraft:stone_bricks","region":"R3","texture":"textures/block/stone_bricks.png"},{"x":0,"y":66,"z":0,"block":"minecraft:stone_bricks","region":"R1","texture":"textures/block/stone_bricks.png"},{"x":0,"y":66,"z":1,"block":"minecraft:stone_bricks","region":"R1","texture":"textures/block/stone_bricks.png"},{"x":0,"y":66,"z":2,"block":"minecraft:stone_bricks","region":"R1","texture":"textures/block/stone_bricks.png"},{"x":0,"y":66,"z":3,"block":"minecraft:stone_bricks","region":"R1","texture":"textures/block/stone_bricks.png"},{"x":0,"y":66,"z":4,"block":"minecraft:stone_bricks","region":"R1","texture":"textures/block/stone_bricks.png"},{"x":0,"y":66,"z":5,"block":"minecraft:stone_bricks","region":"R1","texture":"textures/block/stone_bricks.png"},{"x":0,"y":66,"z":6,"block":"minecraft:stone_bricks","region":"R3","texture":"textures/block/stone_bricks.png"},{"x":0,"y":66,"z":7,"block":"minecraft:stone_bricks","region":"R3","texture":"textures/block/stone_bricks.png"},{"x":0,"y":66,"z":8,"block":"minecraft:stone_bricks","region":"R3","texture":"textures/block/stone_bricks.png"},{"x":0,"y":66,"z":9,"block":"minecraft:stone_bricks","region":"R3","texture":"textures/block/stone_bricks.png"},{"x":0,"y":66,"z":10,"block":"minecraft:stone_bricks","region":"R3","texture":"textures/block/stone_bricks.png"},{"x":0,"y":66,"z":11,"block":"minecraft:stone_bricks","region":"R3","texture":"textures/block/stone_bricks.png"},{"x":0,"y":67,"z":0,"block":"minecraft:stone_bricks","region":"R1","texture":"textures/block/stone_bricks.png"},{"x":0,"y":67,"z":1,"block":"minecraft:stone_bricks","region":"R1","texture":"textures/block/stone_bricks.png"},{"x":0,"y":67,"z":2,"block":"minecraft:stone_bricks","region":"R1","texture":"textures/block/stone_bricks.png"},{"x":0,"y":67,"z":3,"block":"minecraft:stone_bricks","region":"R1","texture":"textures/block/stone_bricks.png"},{"x":0,"y":67,"z":4,"block":"minecraft:stone_bricks","region":"R1","texture":"textures/block/stone_bricks.png"},{"x":0,"y":67,"z":5,"block":"minecraft:stone_bricks","region":"R1","texture":"textures/block/stone_bricks.png"},{"x":0,"y":67,"z":6,"block":"minecraft:stone_bricks","region":"R3","texture":"textures/block/stone_bricks.png"},{"x":0,"y":67,"z":7,"block":"minecraft:stone_bricks","region":"R3","texture":"textures/block/stone_bricks.png"},{"x":0,"y":67,"z":8,"block":"minecraft:stone_bricks","region":"R3","texture":"textures/block/stone_bricks.png"},{"x":0,"y":67,"z":9,"block":"minecraft:stone_bricks","region":"R3","texture":"textures/block/stone_bricks.png"},{"x":0,"y":67,"z":10,"block":"minecraft:stone_bricks","region":"R3","texture":"textures/block/stone_bricks.png"},{"x":0,"y":67,"z":11,"block":"minecraft:stone_bricks","region":"R3","texture":"textures/block/stone_bricks.png"},{"x":0,"y":68,"z":0,"block":"minecraft:stone_bricks","region":"R1","texture":"textures/block/stone_bricks.png"},{"x":0,"y":68,"z":1,"block":"minecraft:stone_bricks","region":"R1","texture":"textures/block/stone_bricks.png"},{"x":0,"y":68,"z":2,"block":"minecraft:stone_bricks","region":"R1","texture":"textures/block/stone_bricks.png"},{"x":0,"y":68,"z":3,"block":"minecraft:stone_bricks","region":"R1","texture":"textures/block/stone_bricks.png"},{"x":0,"y":68,"z":4,"block":"minecraft:stone_bricks","region":"R1","texture":"textures/block/stone_bricks.png"},{"x":0,"y":68,"z":5,"block":"minecraft:stone_bricks","region":"R1","texture":"textures/block/stone_bricks.png"},{"x":0,"y":68,"z":6,"block":"minecraft:stone_bricks","region":"R3","texture":"textures/block/stone_bricks.png"},{"x":0,"y":68,"z":7,"block":"minecraft:stone_bricks","region":"R3","texture":"textures/block/stone_bricks.png"},{"x":0,"y":68,"z":8,"block":"minecraft:stone_bricks","region":"R3","texture":"textures/block/stone_bricks.png"},{"x":0,"y":68,"z":9,"block":"minecraft:stone_bricks","region":"R3","texture":"textures/block/stone_bricks.png"},{"x":0,"y":68,"z":10,"block":"minecraft:stone_bricks","region":"R3","texture":"textures/block/stone_bricks.png"},{"x":0,"y":68,"z":11,"block":"minecraft:stone_bricks","region":"R3","texture":"textures/block/stone_bricks.png"},{"x":0,"y":69,"z":0,"block":"minecraft:stone_bricks","region":"R1","texture":"textures/block/stone_bricks.png"},{"x":0,"y":69,"z":1,"block":"minecraft:stone_bricks","region":"R1","texture":"textures/block/stone_bricks.png"},{"x":0,"y":69,"z":2,"block":"minecraft:stone_bricks","region":"R1","texture":"textures/block/stone_bricks.png"},{"x":0,"y":69,"z":3,"block":"minecraft:stone_bricks","region":"R1","texture":"textures/block/stone_bricks.png"},{"x":0,"y":69,"z":4,"block":"minecraft:stone_bricks","region":"R1","texture":"textures/block/stone_bricks.png"},{"x":0,"y":69,"z":5,"block":"minecraft:stone_bricks","region":"R1","texture":"textures/block/stone_bricks.png"},{"x":0,"y":69,"z":6,"block":"minecraft:stone_bricks","region":"R3","texture":"textures/block/stone_bricks.png"},{"x":0,"y":69,"z":7,"block":"minecraft:stone_bricks","region":"R3","texture":"textures/block/stone_bricks.png"},{"x":0,"y":69,"z":8,"block":"minecraft:stone_bricks","region":"R3","texture":"textures/block/stone_bricks.png"},{"x":0,"y":69,"z":9,"block":"minecraft:stone_bricks","region":"R3","texture":"textures/block/stone_bricks.png"},{"x":0,"y":69,"z":10,"block":"minecraft:stone_bricks","region":"R3","texture":"textures/block/stone_bricks.png"},{"x":0,"y":69,"z":11,"block":"minecraft:stone_bricks","region":"R3","texture":"textures/block/stone_bricks.png"},{"x":0,"y":70,"z":0,"block":"minecraft:stone_bricks","region":"R1","texture":"textures/block/stone_bricks.png"},{"x":0,"y":70,"z":1,"block":"minecraft:stone_bricks","region":"R1","texture":"textures/block/stone_bricks.png"},{"x":0,"y":70,"z":2,"block":"minecraft:stone_bricks","region":"R1","texture":"textures/block/stone_bricks.png"},{"x":0,"y":70,"z":3,"block":"minecraft:stone_bricks","region":"R1","texture":"textures/block/stone_bricks.png"},{"x":0,"y":70,"z":4,"block":"minecraft:stone_bricks","region":"R1","texture":"textures/block/stone_bricks.png"},{"x":0,"y":70,"z":5,"block":"minecraft:stone_bricks","region":"R1","texture":"textures/block/stone_bricks.png"},{"x":0,"y":70,"z":11,"block":"minecraft:stone_bricks","region":"R3","texture":"textures/block/stone_bricks.png"},{"x":1,"y":64,"z":0,"block":"minecraft:stone_bricks","region":"R1","texture":"textures/block/stone_bricks.png"},{"x":1,"y":64,"z":1,"block":"minecraft:stone_bricks","region":"R1","texture":"textures/block/stone_bricks.png"},{"x":1,"y":64,"z":2,"block":"minecraft:stone_bricks","region":"R1","texture":"textures/block/stone_bricks.png"},{"x":1,"y":64,"z":3,"block":"minecraft:stone_bricks","region":"R1","texture":"textures/block/stone_bricks.png"},{"x":1,"y":64,"z":4,"block":"minecraft:stone_bricks","region":"R1","texture":"textures/block/stone_bricks.png"},{"x":1,"y":64,"z":5,"block":"minecraft:stone_bricks","region":"R1","texture":"textures/block/stone_bricks.png"},{"x":1,"y":64,"z":6,"block":"minecraft:stone_bricks","region":"R3","texture":"textures/block/stone_bricks.png"},{"x":1,"y":64,"z":7,"block":"minecraft:stone_bricks","region":"R3","texture":"textures/block/stone_bricks.png"},{"x":1,"y":64,"z":8,"block":"minecraft:stone_bricks","region":"R3","texture":"textures/block/stone_bricks.png"},{"x":1,"y":64,"z":9,"block":"minecraft:stone_bricks","region":"R3","texture":"textures/block/stone_bricks.png"},{"x":1,"y":64,"z":10,"block":"minecraft:stone_bricks","region":"R3","texture":"textures/block/stone_bricks.png"},{"x":1,"y":64,"z":11,"block":"minecraft:stone_bricks","region":"R3","texture":"textures/block/stone_bricks.png"},{"x":1,"y":65,"z":0,"block":"minecraft:stone_bricks","region":"R1","texture":"textures/block/stone_bricks.png"},{"x":1,"y":65,"z":1,"block":"minecraft:lantern","region":"R1","texture":"textures/block/lantern.png"},{"x":1,"y":65,"z":5,"block":"minecraft:stone_bricks","region":"R1","texture":"textures/block/stone_bricks.png"},{"x":1,"y":65,"z":11,"block":"minecraft:stone_bricks","region":"R3","texture":"textures/block/stone_bricks.png"},{"x":1,"y":66,"z":0,"block":"minecraft:stone_bricks","region":"R1","texture":"textures/block/stone_bricks.png"},{"x":1,"y":66,"z":5,"block":"minecraft:stone_bricks","region":"R1","texture":"textures/block/stone_bricks.png"},{"x":1,"y":66,"z":11,"block":"minecraft:stone_bricks","region":"R3","texture":"textures/block/stone_bricks.png"},{"x":1,"y":67,"z":0,"block":"minecraft:stone_bricks","region":"R1","texture":"textures/block/stone_bricks.png"},{"x":1,"y":67,"z":1,"block":"minecraft:lantern","region":"R1","texture":"textures/block/lantern.png"},{"x":1,"y":67,"z":5,"block":"minecraft:stone_bricks","region":"R1","texture":"textures/block/stone_bricks.png"},{"x":1,"y":67,"z":11,"block":"minecraft:stone_bricks","region":"R3","texture":"textures/block/stone_bricks.png"},{"x":1,"y":68,"z":0,"block":"minecraft:stone_bricks","region":"R1","texture":"textures/block/stone_bricks.png"},{"x":1,"y":68,"z":5,"block":"minecraft:stone_bricks","region":"R1","texture":"textures/block/stone_bricks.png"},{"x":1,"y":68,"z":11,"block":"minecraft:stone_bricks","region":"R3","texture":"textures/block/stone_bricks.png"},{"x":1,"y":69,"z":0,"block":"minecraft:stone_bricks","region":"R1","texture":"textures/block/stone_bricks.png"},{"x":1,"y":69,"z":5,"block":"minecraft:stone_bricks","region":"R1","texture":"textures/block/stone_bricks.png"},{"x":1,"y":69,"z":11,"block":"minecraft:stone_bricks","region":"R3","texture":"textures/block/stone_bricks.png"},{"x":1,"y":70,"z":0,"block":"minecraft:stone_bricks","region":"R1","texture":"textures/block/stone_bricks.png"},{"x":1,"y":70,"z":1,"block":"minecraft:stone_bricks","region":"R1","texture":"textures/block/stone_bricks.png"},{"x":1,"y":70,"z":2,"block":"minecraft:stone_bricks","region":"R1","texture":"textures/block/stone_bricks.png"},{"x":1,"y":70,"z":3,"block":"minecraft:stone_bricks","region":"R1","texture":"textures/block/stone_bricks.png"},{"x":1,"y":70,"z":4,"block":"minecraft:stone_bricks","region":"R1","texture":"textures/block/stone_bricks.png"},{"x":1,"y":70,"z":5,"block":"minecraft:stone_bricks","region":"R1","texture":"textures/block/stone_bricks.png"},{"x":1,"y":70,"z":11,"block":"minecraft:stone_bricks","region":"R3","texture":"textures/block/stone_bricks.png"},{"x":2,"y":64,"z":0,"block":"minecraft:stone_bricks","region":"R1","texture":"textures/block/stone_bricks.png"},{"x":2,"y":64,"z":1,"block":"minecraft:stone_bricks","region":"R1","texture":"textures/block/stone_bricks.png"},{"x":2,"y":64,"z":2,"block":"minecraft:stone_bricks","region":"R1","texture":"textures/block/stone_bricks.png"},{"x":2,"y":64,"z":3,"block":"minecraft:stone_bricks","region":"R1","texture":"textures/block/stone_bricks.png"},{"x":2,"y":64,"z":4,"block":"minecraft:stone_bricks","region":"R1","texture":"textures/block/stone_bricks.png"},{"x":2,"y":64,"z":5,"block":"minecraft:stone_bricks","region":"R1","texture":"textures/block/stone_bricks.png"},{"x":2,"y":64,"z":6,"block":"minecraft:stone_bricks","region":"R3","texture":"textures/block/stone_bricks.png"},{"x":2,"y":64,"z":7,"block":"minecraft:stone_bricks","region":"R3","texture":"textures/block/stone_bricks.png"},{"x":2,"y":64,"z":8,"block":"minecraft:stone_bricks","region":"R3","texture":"textures/block/stone_bricks.png"},{"x":2,"y":64,"z":9,"block":"minecraft:stone_bricks","region":"R3","texture":"textures/block/stone_bricks.png"},{"x":2,"y":64,"z":10,"block":"minecraft:stone_bricks","region":"R3","texture":"textures/block/stone_bricks.png"},{"x":2,"y":64,"z":11,"block":"minecraft:stone_bricks","region":"R3","texture":"textures/block/stone_bricks.png"},{"x":2,"y":65,"z":0,"block":"minecraft:stone_bricks","region":"R1","texture":"textures/block/stone_bricks.png"},{"x":2,"y":65,"z":1,"block":"minecraft:spruce_planks","region":"R1","texture":"textures/block/spruce_planks.png"},{"x":2,"y":65,"z":5,"block":"minecraft:stone_bricks","region":"R1","texture":"textures/block/stone_bricks.png"},{"x":2,"y":65,"z":11,"block":"minecraft:stone_bricks","region":"R3","texture":"textures/block/stone_bricks.png"},{"x":2,"y":66,"z":0,"block":"minecraft:stone_bricks","region":"R1","texture":"textures/block/stone_bricks.png"},{"x":2,"y":66,"z":5,"block":"minecraft:stone_bricks","region":"R1","texture":"textures/block/stone_bricks.png"},{"x":2,"y":66,"z":11,"block":"minecraft:stone_bricks","region":"R3","texture":"textures/block/stone_bricks.png"},{"x":2,"y":67,"z":0,"block":"minecraft:stone_bricks","region":"R1","texture":"textures/block/stone_bricks.png"},{"x":2,"y":67,"z":5,"block":"minecraft:stone_bricks","region":"R1","texture":"textures/block/stone_bricks.png"},{"x":2,"y":67,"z":11,"block":"minecraft:stone_bricks","region":"R3","texture":"textures/block/stone_bricks.png"},{"x":2,"y":68,"z":0,"block":"minecraft:stone_bricks","region":"R1","texture":"textures/block/stone_bricks.png"},{"x":2,"y":68,"z":5,"block":"minecraft:stone_bricks","region":"R1","texture":"textures/block/stone_bricks.png"},{"x":2,"y":68,"z":11,"block":"minecraft:stone_bricks","region":"R3","texture":"textures/block/stone_bricks.png"},{"x":2,"y":69,"z":0,"block":"minecraft:stone_bricks","region":"R1","texture":"textures/block/stone_bricks.png"},{"x":2,"y":69,"z":5,"block":"minecraft:stone_bricks","region":"R1","texture":"textures/block/stone_bricks.png"},{"x":2,"y":69,"z":11,"block":"minecraft:stone_bricks","region":"R3","texture":"textures/block/stone_bricks.png"},{"x":2,"y":70,"z":0,"block":"minecraft:stone_bricks","region":"R1","texture":"textures/block/stone_bricks.png"},{"x":2,"y":70,"z":1,"block":"minecraft:stone_bricks","region":"R1","texture":"textures/block/stone_bricks.png"},{"x":2,"y":70,"z":2,"block":"minecraft:stone_bricks","region":"R1","texture":"textures/block/stone_bricks.png"},{"x":2,"y":70,"z":3,"block":"minecraft:stone_bricks","region":"R1","texture":"textures/block/stone_bricks.png"},{"x":2,"y":70,"z":4,"block":"minecraft:stone_bricks","region":"R1","texture":"textures/block/stone_bricks.png"},{"x":2,"y":70,"z":5,"block":"minecraft:stone_bricks","region":"R1","texture":"textures/block/stone_bricks.png"},{"x":2,"y":70,"z":11,"block":"minecraft:stone_bricks","region":"R3","texture":"textures/block/stone_bricks.png"},{"x":3,"y":64,"z":0,"block":"minecraft:stone_bricks","region":"R1","texture":"textures/block/stone_bricks.png"},{"x":3,"y":64,"z":1,"block":"minecraft:stone_bricks","region":"R1","texture":"textures/block/stone_bricks.png"},{"x":3,"y":64,"z":2,"block":"minecraft:stone_bricks","region":"R1","texture":"textures/block/stone_bricks.png"},{"x":3,"y":64,"z":3,"block":"minecraft:stone_bricks","region":"R1","texture":"textures/block/stone_bricks.png"},{"x":3,"y":64,"z":4,"block":"minecraft:stone_bricks","region":"R1","texture":"textures/block/stone_bricks.png"},{"x":3,"y":64,"z":5,"block":"minecraft:stone_bricks","region":"R1","texture":"textures/block/stone_bricks.png"},{"x":3,"y":64,"z":6,"block":"minecraft:stone_bricks","region":"R3","texture":"textures/block/stone_bricks.png"},{"x":3,"y":64,"z":7,"block":"minecraft:stone_bricks","region":"R3","texture":"textures/block/stone_bricks.png"},{"x":3,"y":64,"z":8,"block":"minecraft:stone_bricks","region":"R3","texture":"textures/block/stone_bricks.png"},{"x":3,"y":64,"z":9,"block":"minecraft:stone_bricks","region":"R3","texture":"textures/block/stone_bricks.png"},{"x":3,"y":64,"z":10,"block":"minecraft:stone_bricks","region":"R3","texture":"textures/block/stone_bricks.png"},{"x":3,"y":64,"z":11,"block":"minecraft:stone_bricks","region":"R3","texture":"textures/block/stone_bricks.png"},{"x":3,"y":65,"z":0,"block":"minecraft:stone_bricks","region":"R1","texture":"textures/block/stone_bricks.png"},{"x":3,"y":65,"z":1,"block":"minecraft:spruce_planks","region":"R1","texture":"textures/block/spruce_planks.png"},{"x":3,"y":65,"z":5,"block":"minecraft:stone_bricks","region":"R1","texture":"textures/block/stone_bricks.png"},{"x":3,"y":65,"z":11,"block":"minecraft:stone_bricks","region":"R3","texture":"textures/block/stone_bricks.png"},{"x":3,"y":66,"z":0,"block":"minecraft:stone_bricks","region":"R1","texture":"textures/block/stone_bricks.png"},{"x":3,"y":66,"z":5,"block":"minecraft:stone_bricks","region":"R1","texture":"textures/block/stone_bricks.png"},{"x":3,"y":66,"z":11,"block":"minecraft:glass_pane","region":"R3","texture":"textures/block/glass_pane.png"},{"x":3,"y":67,"z":0,"block":"minecraft:stone_bricks","region":"R1","texture":"textures/block/stone_bricks.png"},{"x":3,"y":67,"z":5,"block":"minecraft:stone_bricks","region":"R1","texture":"textures/block/stone_bricks.png"},{"x":3,"y":67,"z":11,"block":"minecraft:stone_bricks","region":"R3","texture":"textures/block/stone_bricks.png"},{"x":3,"y":68,"z":0,"block":"minecraft:stone_bricks","region":"R1","texture":"textures/block/stone_bricks.png"},{"x":3,"y":68,"z":5,"block":"minecraft:stone_bricks","region":"R1","texture":"textures/block/stone_bricks.png"},{"x":3,"y":68,"z":11,"block":"minecraft:stone_bricks","region":"R3","texture":"textures/block/stone_bricks.png"},{"x":3,"y":69,"z":0,"block":"minecraft:stone_bricks","region":"R1","texture":"textures/block/stone_bricks.png"},{"x":3,"y":69,"z":5,"block":"minecraft:stone_bricks","region":"R1","texture":"textures/block/stone_bricks.png"},{"x":3,"y":69,"z":11,"block":"minecraft:stone_bricks","region":"R3","texture":"textures/block/stone_bricks.png"},{"x":3,"y":70,"z":0,"block":"minecraft:stone_bricks","region":"R1","texture":"textures/block/stone_bricks.png"},{"x":3,"y":70,"z":1,"block":"minecraft:stone_bricks","region":"R1","texture":"textures/block/stone_bricks.png"},{"x":3,"y":70,"z":2,"block":"minecraft:stone_bricks","region":"R1","texture":"textures/block/stone_bricks.png"},{"x":3,"y":70,"z":3,"block":"minecraft:stone_bricks","region":"R1","texture":"textures/block/stone_bricks.png"},{"x":3,"y":70,"z":4,"block":"minecraft:stone_bricks","region":"R1","texture":"textures/block/stone_bricks.png"},{"x":3,"y":70,"z":5,"block":"minecraft:stone_bricks","region":"R1","texture":"textures/block/stone_bricks.png"},{"x":3,"y":70,"z":11,"block":"minecraft:stone_bricks","region":"R3","texture":"textures/block/stone_bricks.png"},{"x":4,"y":64,"z":0,"block":"minecraft:stone_bricks","region":"R1","texture":"textures/block/stone_bricks.png"},{"x":4,"y":64,"z":1,"block":"minecraft:stone_bricks","region":"R1","texture":"textures/block/stone_bricks.png"},{"x":4,"y":64,"z":2,"block":"minecraft:stone_bricks","region":"R1","texture":"textures/block/stone_bricks.png"},{"x":4,"y":64,"z":3,"block":"minecraft:stone_bricks","region":"R1","texture":"textures/block/stone_bricks.png"},{"x":4,"y":64,"z":4,"block":"minecraft:stone_bricks","region":"R1","texture":"textures/block/stone_bricks.png"},{"x":4,"y":64,"z":5,"block":"minecraft:stone_bricks","region":"R1","texture":"textures/block/stone_bricks.png"},{"x":4,"y":64,"z":6,"block":"minecraft:stone_bricks","region":"R3","texture":"textures/block/stone_bricks.png"},{"x":4,"y":64,"z":7,"block":"minecraft:stone_bricks","region":"R3","texture":"textures/block/stone_bricks.png"},{"x":4,"y":64,"z":8,"block":"minecraft:stone_bricks","region":"R3","texture":"textures/block/stone_bricks.png"},{"x":4,"y":64,"z":9,"block":"minecraft:stone_bricks","region":"R3","texture":"textures/block/stone_bricks.png"},{"x":4,"y":64,"z":10,"block":"minecraft:stone_bricks","region":"R3","texture":"textures/block/stone_bricks.png"},{"x":4,"y":64,"z":11,"block":"minecraft:stone_bricks","region":"R3","texture":"textures/block/stone_bricks.png"},{"x":4,"y":65,"z":0,"block":"minecraft:stone_bricks","region":"R1","texture":"textures/block/stone_bricks.png"},{"x":4,"y":65,"z":5,"block":"minecraft:stone_bricks","region":"R1","texture":"textures/block/stone_bricks.png"},{"x":4,"y":65,"z":11,"block":"minecraft:stone_bricks","region":"R3","texture":"textures/block/stone_bricks.png"},{"x":4,"y":66,"z":0,"block":"minecraft:stone_bricks","region":"R1","texture":"textures/block/stone_bricks.png"},{"x":4,"y":66,"z":5,"block":"minecraft:stone_bricks","region":"R1","texture":"textures/block/stone_bricks.png"},{"x":4,"y":66,"z":11,"block":"minecraft:stone_bricks","region":"R3","texture":"textures/block/stone_bricks.png"},{"x":4,"y":67,"z":0,"block":"minecraft:stone_bricks","region":"R1","texture":"textures/block/stone_bricks.png"},{"x":4,"y":67,"z":5,"block":"minecraft:stone_bricks","region":"R1","texture":"textures/block/stone_bricks.png"},{"x":4,"y":67,"z":11,"block":"minecraft:stone_bricks","region":"R3","texture":"textures/block/stone_bricks.png"},{"x":4,"y":68,"z":0,"block":"minecraft:stone_bricks","region":"R1","texture":"textures/block/stone_bricks.png"},{"x":4,"y":68,"z":5,"block":"minecraft:stone_bricks","region":"R1","texture":"textures/block/stone_bricks.png"},{"x":4,"y":68,"z":11,"block":"minecraft:stone_bricks","region":"R3","texture":"textures/block/stone_bricks.png"},{"x":4,"y":69,"z":0,"block":"minecraft:stone_bricks","region":"R1","texture":"textures/block/stone_bricks.png"},{"x":4,"y":69,"z":5,"block":"minecraft:stone_bricks","region":"R1","texture":"textures/block/stone_bricks.png"},{"x":4,"y":69,"z":11,"block":"minecraft:stone_bricks","region":"R3","texture":"textures/block/stone_bricks.png"},{"x":4,"y":70,"z":0,"block":"minecraft:stone_bricks","region":"R1","texture":"textures/block/stone_bricks.png"},{"x":4,"y":70,"z":1,"block":"minecraft:stone_bricks","region":"R1","texture":"textures/block/stone_bricks.png"},{"x":4,"y":70,"z":2,"block":"minecraft:stone_bricks","region":"R1","texture":"textures/block/stone_bricks.png"},{"x":4,"y":70,"z":3,"block":"minecraft:stone_bricks","region":"R1","texture":"textures/block/stone_bricks.png"},{"x":4,"y":70,"z":4,"block":"minecraft:stone_bricks","region":"R1","texture":"textures/block/stone_bricks.png"},{"x":4,"y":70,"z":5,"block":"minecraft:stone_bricks","region":"R1","texture":"textures/block/stone_bricks.png"},{"x":4,"y":70,"z":11,"block":"minecraft:stone_bricks","region":"R3","texture":"textures/block/stone_bricks.png"},{"x":5,"y":64,"z":0,"block":"minecraft:stone_bricks","region":"R1","texture":"textures/block/stone_bricks.png"},{"x":5,"y":64,"z":1,"block":"minecraft:stone_bricks","region":"R1","texture":"textures/block/stone_bricks.png"},{"x":5,"y":64,"z":2,"block":"minecraft:stone_bricks","region":"R1","texture":"textures/block/stone_bricks.png"},{"x":5,"y":64,"z":3,"block":"minecraft:stone_bricks","region":"R1","texture":"textures/block/stone_bricks.png"},{"x":5,"y":64,"z":4,"block":"minecraft:stone_bricks","region":"R1","texture":"textures/block/stone_bricks.png"},{"x":5,"y":64,"z":5,"block":"minecraft:stone_bricks","region":"R1","texture":"textures/block/stone_bricks.png"},{"x":5,"y":64,"z":6,"block":"minecraft:stone_bricks","region":"R3","texture":"textures/block/stone_bricks.png"},{"x":5,"y":64,"z":7,"block":"minecraft:stone_bricks","region":"R3","texture":"textures/block/stone_bricks.png"},{"x":5,"y":64,"z":8,"block":"minecraft:stone_bricks","region":"R3","texture":"textures/block/stone_bricks.png"},{"x":5,"y":64,"z":9,"block":"minecraft:stone_bricks","region":"R3","texture":"textures/block/stone_bricks.png"},{"x":5,"y":64,"z":10,"block":"minecraft:stone_bricks","region":"R3","texture":"textures/block/stone_bricks.png"},{"x":5,"y":64,"z":11,"block":"minecraft:stone_bricks","region":"R3","texture":"textures/block/stone_bricks.png"},{"x":5,"y":65,"z":0,"block":"minecraft:stone_bricks","region":"R1","texture":"textures/block/stone_bricks.png"},{"x":5,"y":65,"z":1,"block":"minecraft:stone_bricks","region":"R1","texture":"textures/block/stone_bricks.png"},{"x":5,"y":65,"z":2,"block":"minecraft:stone_bricks","region":"R1","texture":"textures/block/stone_bricks.png"},{"x":5,"y":65,"z":3,"block":"minecraft:stone_bricks","region":"R1","texture":"textures/block/stone_bricks.png"},{"x":5,"y":65,"z":4,"block":"minecraft:stone_bricks","region":"R1","texture":"textures/block/stone_bricks.png"},{"x":5,"y":65,"z":5,"block":"minecraft:stone_bricks","region":"R1","texture":"textures/block/stone_bricks.png"},{"x":5,"y":65,"z":7,"block":"minecraft:oak_planks","region":"R3","texture":"textures/block/oak_planks.png"},{"x":5,"y":65,"z":8,"block":"minecraft:oak_planks","region":"R3","texture":"textures/block/oak_planks.png"},{"x":5,"y":65,"z":11,"block":"minecraft:stone_bricks","region":"R3","texture":"textures/block/stone_bricks.png"},{"x":5,"y":66,"z":0,"block":"minecraft:stone_bricks","region":"R1","texture":"textures/block/stone_bricks.png"},{"x":5,"y":66,"z":1,"block":"minecraft:stone_bricks","region":"R1","texture":"textures/block/stone_bricks.png"},{"x":5,"y":66,"z":2,"block":"minecraft:stone_bricks","region":"R1","texture":"textures/block/stone_bricks.png"},{"x":5,"y":66,"z":3,"block":"minecraft:stone_bricks","region":"R1","texture":"textures/block/stone_bricks.png"},{"x":5,"y":66,"z":4,"block":"minecraft:stone_bricks","region":"R1","texture":"textures/block/stone_bricks.png"},{"x":5,"y":66,"z":5,"block":"minecraft:stone_bricks","region":"R1","texture":"textures/block/stone_bricks.png"},{"x":5,"y":66,"z":11,"block":"minecraft:stone_bricks","region":"R3","texture":"textures/block/stone_bricks.png"},{"x":5,"y":67,"z":0,"block":"minecraft:stone_bricks","region":"R1","texture":"textures/block/stone_bricks.png"},{"x":5,"y":67,"z":1,"block":"minecraft:stone_bricks","region":"R1","texture":"textures/block/stone_bricks.png"},{"x":5,"y":67,"z":2,"block":"minecraft:stone_bricks","region":"R1","texture":"textures/block/stone_bricks.png"},{"x":5,"y":67,"z":3,"block":"minecraft:stone_bricks","region":"R1","texture":"textures/block/stone_bricks.png"},{"x":5,"y":67,"z":4,"block":"minecraft:stone_bricks","region":"R1","texture":"textures/block/stone_bricks.png"},{"x":5,"y":67,"z":5,"block":"minecraft:stone_bricks","region":"R1","texture":"textures/block/stone_bricks.png"},{"x":5,"y":67,"z":11,"block":"minecraft:stone_bricks","region":"R3","texture":"textures/block/stone_bricks.png"},{"x":5,"y":68,"z":0,"block":"minecraft:stone_bricks","region":"R1","texture":"textures/block/stone_bricks.png"},{"x":5,"y":68,"z":1,"block":"minecraft:stone_bricks","region":"R1","texture":"textures/block/stone_bricks.png"},{"x":5,"y":68,"z":2,"block":"minecraft:stone_bricks","region":"R1","texture":"textures/block/stone_bricks.png"},{"x":5,"y":68,"z":3,"block":"minecraft:stone_bricks","region":"R1","texture":"textures/block/stone_bricks.png"},{"x":5,"y":68,"z":4,"block":"minecraft:stone_bricks","region":"R1","texture":"textures/block/stone_bricks.png"},{"x":5,"y":68,"z":5,"block":"minecraft:stone_bricks","region":"R1","texture":"textures/block/stone_bricks.png"},{"x":5,"y":68,"z":11,"block":"minecraft:stone_bricks","region":"R3","texture":"textures/block/stone_bricks.png"},{"x":5,"y":69,"z":0,"block":"minecraft:stone_bricks","region":"R1","texture":"textures/block/stone_bricks.png"},{"x":5,"y":69,"z":1,"block":"minecraft:stone_bricks","region":"R1","texture":"textures/block/stone_bricks.png"},{"x":5,"y":69,"z":2,"block":"minecraft:stone_bricks","region":"R1","texture":"textures/block/stone_bricks.png"},{"x":5,"y":69,"z":3,"block":"minecraft:stone_bricks","region":"R1","texture":"textures/block/stone_bricks.png"},{"x":5,"y":69,"z":4,"block":"minecraft:stone_bricks","region":"R1","texture":"textures/block/stone_bricks.png"},{"x":5,"y":69,"z":5,"block":"minecraft:stone_bricks","region":"R1","texture":"textures/block/stone_bricks.png"},{"x":5,"y":69,"z":11,"block":"minecraft:stone_bricks","region":"R3","texture":"textures/block/stone_bricks.png"},{"x":5,"y":70,"z":0,"block":"minecraft:stone_bricks","region":"R1","texture":"textures/block/stone_bricks.png"},{"x":5,"y":70,"z":1,"block":"minecraft:stone_bricks","region":"R1","texture":"textures/block/stone_bricks.png"},{"x":5,"y":70,"z":2,"block":"minecraft:stone_bricks","region":"R1","texture":"textures/block/stone_bricks.png"},{"x":5,"y":70,"z":3,"block":"minecraft:stone_bricks","region":"R1","texture":"textures/block/stone_bricks.png"},{"x":5,"y":70,"z":4,"block":"minecraft:stone_bricks","region":"R1","texture":"textures/block/stone_bricks.png"},{"x":5,"y":70,"z":5,"block":"minecraft:stone_bricks","region":"R1","texture":"textures/block/stone_bricks.png"},{"x":5,"y":70,"z":11,"block":"minecraft:stone_bricks","region":"R3","texture":"textures/block/stone_bricks.png"},{"x":6,"y":64,"z":0,"block":"minecraft:stone_bricks","region":"R2","texture":"textures/block/stone_bricks.png"},{"x":6,"y":64,"z":1,"block":"minecraft:stone_bricks","region":"R2","texture":"textures/block/stone_bricks.png"},{"x":6,"y":64,"z":2,"block":"minecraft:stone_bricks","region":"R2","texture":"textures/block/stone_bricks.png"},{"x":6,"y":64,"z":3,"block":"minecraft:stone_bricks","region":"R2","texture":"textures/block/stone_bricks.png"},{"x":6,"y":64,"z":4,"block":"minecraft:stone_bricks","region":"R2","texture":"textures/block/stone_bricks.png"},{"x":6,"y":64,"z":5,"block":"minecraft:stone_bricks","region":"R2","texture":"textures/block/stone_bricks.png"},{"x":6,"y":64,"z":6,"block":"minecraft:stone_bricks","region":"R3","texture":"textures/block/stone_bricks.png"},{"x":6,"y":64,"z":7,"block":"minecraft:stone_bricks","region":"R3","texture":"textures/block/stone_bricks.png"},{"x":6,"y":64,"z":8,"block":"minecraft:stone_bricks","region":"R3","texture":"textures/block/stone_bricks.png"},{"x":6,"y":64,"z":9,"block":"minecraft:stone_bricks","region":"R3","texture":"textures/block/stone_bricks.png"},{"x":6,"y":64,"z":10,"block":"minecraft:stone_bricks","region":"R3","texture":"textures/block/stone_bricks.png"},{"x":6,"y":64,"z":11,"block":"minecraft:stone_bricks","region":"R3","texture":"textures/block/stone_bricks.png"},{"x":6,"y":65,"z":0,"block":"minecraft:stone_bricks","region":"R2","texture":"textures/block/stone_bricks.png"},{"x":6,"y":65,"z":1,"block":"minecraft:stone_bricks","region":"R2","texture":"textures/block/stone_bricks.png"},{"x":6,"y":65,"z":2,"block":"minecraft:stone_bricks","region":"R2","texture":"textures/block/stone_bricks.png"},{"x":6,"y":65,"z":3,"block":"minecraft:stone_bricks","region":"R2","texture":"textures/block/stone_bricks.png"},{"x":6,"y":65,"z":4,"block":"minecraft:stone_bricks","region":"R2","texture":"textures/block/stone_bricks.png"},{"x":6,"y":65,"z":5,"block":"minecraft:stone_bricks","region":"R2","texture":"textures/block/stone_bricks.png"},{"x":6,"y":65,"z":7,"block":"minecraft:oak_planks","region":"R3","texture":"textures/block/oak_planks.png"},{"x":6,"y":65,"z":8,"block":"minecraft:oak_planks","region":"R3","texture":"textures/block/oak_planks.png"},{"x":6,"y":65,"z":11,"block":"minecraft:stone_bricks","region":"R3","texture":"textures/block/stone_bricks.png"},{"x":6,"y":66,"z":0,"block":"minecraft:stone_bricks","region":"R2","texture":"textures/block/stone_bricks.png"},{"x":6,"y":66,"z":1,"block":"minecraft:stone_bricks","region":"R2","texture":"textures/block/stone_bricks.png"},{"x":6,"y":66,"z":2,"block":"minecraft:stone_bricks","region":"R2","texture":"textures/block/stone_bricks.png"},{"x":6,"y":66,"z":3,"block":"minecraft:stone_bricks","region":"R2","texture":"textures/block/stone_bricks.png"},{"x":6,"y":66,"z":4,"block":"minecraft:stone_bricks","region":"R2","texture":"textures/block/stone_bricks.png"},{"x":6,"y":66,"z":5,"block":"minecraft:stone_bricks","region":"R2","texture":"textures/block/stone_bricks.png"},{"x":6,"y":66,"z":11,"block":"minecraft:stone_bricks","region":"R3","texture":"textures/block/stone_bricks.png"},{"x":6,"y":67,"z":0,"block":"minecraft:stone_bricks","region":"R2","texture":"textures/block/stone_bricks.png"},{"x":6,"y":67,"z":1,"block":"minecraft:stone_bricks","region":"R2","texture":"textures/block/stone_bricks.png"},{"x":6,"y":67,"z":2,"block":"minecraft:stone_bricks","region":"R2","texture":"textures/block/stone_bricks.png"},{"x":6,"y":67,"z":3,"block":"minecraft:stone_bricks","region":"R2","texture":"textures/block/stone_bricks.png"},{"x":6,"y":67,"z":4,"block":"minecraft:stone_bricks","region":"R2","texture":"textures/block/stone_bricks.png"},{"x":6,"y":67,"z":5,"block":"minecraft:stone_bricks","region":"R2","texture":"textures/block/stone_bricks.png"},{"x":6,"y":67,"z":11,"block":"minecraft:stone_bricks","region":"R3","texture":"textures/block/stone_bricks.png"},{"x":6,"y":68,"z":0,"block":"minecraft:stone_bricks","region":"R2","texture":"textures/block/stone_bricks.png"},{"x":6,"y":68,"z":1,"block":"minecraft:stone_bricks","region":"R2","texture":"textures/block/stone_bricks.png"},{"x":6,"y":68,"z":2,"block":"minecraft:stone_bricks","region":"R2","texture":"textures/block/stone_bricks.png"},{"x":6,"y":68,"z":3,"block":"minecraft:stone_bricks","region":"R2","texture":"textures/block/stone_bricks.png"},{"x":6,"y":68,"z":4,"block":"minecraft:stone_bricks","region":"R2","texture":"textures/block/stone_bricks.png"},{"x":6,"y":68,"z":5,"block":"minecraft:stone_bricks","region":"R2","texture":"textures/block/stone_bricks.png"},{"x":6,"y":68,"z":11,"block":"minecraft:stone_bricks","region":"R3","texture":"textures/block/stone_bricks.png"},{"x":6,"y":69,"z":0,"block":"minecraft:stone_bricks","region":"R2","texture":"textures/block/stone_bricks.png"},{"x":6,"y":69,"z":1,"block":"minecraft:stone_bricks","region":"R2","texture":"textures/block/stone_bricks.png"},{"x":6,"y":69,"z":2,"block":"minecraft:stone_bricks","region":"R2","texture":"textures/block/stone_bricks.png"},{"x":6,"y":69,"z":3,"block":"minecraft:stone_bricks","region":"R2","texture":"textures/block/stone_bricks.png"},{"x":6,"y":69,"z":4,"block":"minecraft:stone_bricks","region":"R2","texture":"textures/block/stone_bricks.png"},{"x":6,"y":69,"z":5,"block":"minecraft:stone_bricks","region":"R2","texture":"textures/block/stone_bricks.png"},{"x":6,"y":69,"z":11,"block":"minecraft:stone_bricks","region":"R3","texture":"textures/block/stone_bricks.png"},{"x":6,"y":70,"z":0,"block":"minecraft:stone_bricks","region":"R2","texture":"textures/block/stone_bricks.png"},{"x":6,"y":70,"z":1,"block":"minecraft:stone_bricks","region":"R2","texture":"textures/block/stone_bricks.png"},{"x":6,"y":70,"z":2,"block":"minecraft:stone_bricks","region":"R2","texture":"textures/block/stone_bricks.png"},{"x":6,"y":70,"z":3,"block":"minecraft:stone_bricks","region":"R2","texture":"textures/block/stone_bricks.png"},{"x":6,"y":70,"z":4,"block":"minecraft:stone_bricks","region":"R2","texture":"textures/block/stone_bricks.png"},{"x":6,"y":70,"z":5,"block":"minecraft:stone_bricks","region":"R2","texture":"textures/block/stone_bricks.png"},{"x":6,"y":70,"z":11,"block":"minecraft:stone_bricks","region":"R3","texture":"textures/block/stone_bricks.png"},{"x":6,"y":71,"z":0,"block":"minecraft:stone_bricks","region":"R2","texture":"textures/block/stone_bricks.png"},{"x":6,"y":71,"z":1,"block":"minecraft:stone_bricks","region":"R2","texture":"textures/block/stone_bricks.png"},{"x":6,"y":71,"z":2,"block":"minecraft:stone_bricks","region":"R2","texture":"textures/block/stone_bricks.png"},{"x":6,"y":71,"z":3,"block":"minecraft:stone_bricks","region":"R2","texture":"textures/block/stone_bricks.png"},{"x":6,"y":71,"z":4,"block":"minecraft:stone_bricks","region":"R2","texture":"textures/block/stone_bricks.png"},{"x":6,"y":71,"z":5,"block":"minecraft:stone_bricks","region":"R2","texture":"textures/block/stone_bricks.png"},{"x":7,"y":64,"z":0,"block":"minecraft:stone_bricks","region":"R2","texture":"textures/block/stone_bricks.png"},{"x":7,"y":64,"z":1,"block":"minecraft:stone_bricks","region":"R2","texture":"textures/block/stone_bricks.png"},{"x":7,"y":64,"z":2,"block":"minecraft:stone_bricks","region":"R2","texture":"textures/block/stone_bricks.png"},{"x":7,"y":64,"z":3,"block":"minecraft:stone_bricks","region":"R2","texture":"textures/block/stone_bricks.png"},{"x":7,"y":64,"z":4,"block":"minecraft:stone_bricks","region":"R2","texture":"textures/block/stone_bricks.png"},{"x":7,"y":64,"z":5,"block":"minecraft:stone_bricks","region":"R2","texture":"textures/block/stone_bricks.png"},{"x":7,"y":64,"z":6,"block":"minecraft:stone_bricks","region":"R3","texture":"textures/block/stone_bricks.png"},{"x":7,"y":64,"z":7,"block":"minecraft:stone_bricks","region":"R3","texture":"textures/block/stone_bricks.png"},{"x":7,"y":64,"z":8,"block":"minecraft:stone_bricks","region":"R3","texture":"textures/block/stone_bricks.png"},{"x":7,"y":64,"z":9,"block":"minecraft:stone_bricks","region":"R3","texture":"textures/block/stone_bricks.png"},{"x":7,"y":64,"z":10,"block":"minecraft:stone_bricks","region":"R3","texture":"textures/block/stone_bricks.png"},{"x":7,"y":64,"z":11,"block":"minecraft:stone_bricks","region":"R3","texture":"textures/block/stone_bricks.png"},{"x":7,"y":65,"z":0,"block":"minecraft:stone_bricks","region":"R2","texture":"textures/block/stone_bricks.png"},{"x":7,"y":65,"z":5,"block":"minecraft:stone_bricks","region":"R2","texture":"textures/block/stone_bricks.png"},{"x":7,"y":65,"z":11,"block":"minecraft:stone_bricks","region":"R3","texture":"textures/block/stone_bricks.png"},{"x":7,"y":66,"z":0,"block":"minecraft:stone_bricks","region":"R2","texture":"textures/block/stone_bricks.png"},{"x":7,"y":66,"z":5,"block":"minecraft:stone_bricks","region":"R2","texture":"textures/block/stone_bricks.png"},{"x":7,"y":66,"z":11,"block":"minecraft:stone_bricks","region":"R3","texture":"textures/block/stone_bricks.png"},{"x":7,"y":67,"z":0,"block":"minecraft:stone_bricks","region":"R2","texture":"textures/block/stone_bricks.png"},{"x":7,"y":67,"z":1,"block":"minecraft:lantern","region":"R2","texture":"textures/block/lantern.png"},{"x":7,"y":67,"z":5,"block":"minecraft:stone_bricks","region":"R2","texture":"textures/block/stone_bricks.png"},{"x":7,"y":67,"z":11,"block":"minecraft:stone_bricks","region":"R3","texture":"textures/block/stone_bricks.png"},{"x":7,"y":68,"z":0,"block":"minecraft:stone_bricks","region":"R2","texture":"textures/block/stone_bricks.png"},{"x":7,"y":68,"z":5,"block":"minecraft:stone_bricks","region":"R2","texture":"textures/block/stone_bricks.png"},{"x":7,"y":68,"z":11,"block":"minecraft:stone_bricks","region":"R3","texture":"textures/block/stone_bricks.png"},{"x":7,"y":69,"z":0,"block":"minecraft:stone_bricks","region":"R2","texture":"textures/block/stone_bricks.png"},{"x":7,"y":69,"z":5,"block":"minecraft:stone_bricks","region":"R2","texture":"textures/block/stone_bricks.png"},{"x":7,"y":69,"z":11,"block":"minecraft:stone_bricks","region":"R3","texture":"textures/block/stone_bricks.png"},{"x":7,"y":70,"z":0,"block":"minecraft:stone_bricks","region":"R2","texture":"textures/block/stone_bricks.png"},{"x":7,"y":70,"z":5,"block":"minecraft:stone_bricks","region":"R2","texture":"textures/block/stone_bricks.png"},{"x":7,"y":70,"z":11,"block":"minecraft:stone_bricks","region":"R3","texture":"textures/block/stone_bricks.png"},{"x":7,"y":71,"z":0,"block":"minecraft:stone_bricks","region":"R2","texture":"textures/block/stone_bricks.png"},{"x":7,"y":71,"z":1,"block":"minecraft:stone_bricks","region":"R2","texture":"textures/block/stone_bricks.png"},{"x":7,"y":71,"z":2,"block":"minecraft:stone_bricks","region":"R2","texture":"textures/block/stone_bricks.png"},{"x":7,"y":71,"z":3,"block":"minecraft:stone_bricks","region":"R2","texture":"textures/block/stone_bricks.png"},{"x":7,"y":71,"z":4,"block":"minecraft:stone_bricks","region":"R2","texture":"textures/block/stone_bricks.png"},{"x":7,"y":71,"z":5,"block":"minecraft:stone_bricks","region":"R2","texture":"textures/block/stone_bricks.png"},{"x":8,"y":64,"z":0,"block":"minecraft:stone_bricks","region":"R2","texture":"textures/block/stone_bricks.png"},{"x":8,"y":64,"z":1,"block":"minecraft:stone_bricks","region":"R2","texture":"textures/block/stone_bricks.png"},{"x":8,"y":64,"z":2,"block":"minecraft:stone_bricks","region":"R2","texture":"textures/block/stone_bricks.png"},{"x":8,"y":64,"z":3,"block":"minecraft:stone_bricks","region":"R2","texture":"textures/block/stone_bricks.png"},{"x":8,"y":64,"z":4,"block":"minecraft:stone_bricks","region":"R2","texture":"textures/block/stone_bricks.png"},{"x":8,"y":64,"z":5,"block":"minecraft:stone_bricks","region":"R2","texture":"textures/block/stone_bricks.png"},{"x":8,"y":64,"z":6,"block":"minecraft:stone_bricks","region":"R3","texture":"textures/block/stone_bricks.png"},{"x":8,"y":64,"z":7,"block":"minecraft:stone_bricks","region":"R3","texture":"textures/block/stone_bricks.png"},{"x":8,"y":64,"z":8,"block":"minecraft:stone_bricks","region":"R3","texture":"textures/block/stone_bricks.png"},{"x":8,"y":64,"z":9,"block":"minecraft:stone_bricks","region":"R3","texture":"textures/block/stone_bricks.png"},{"x":8,"y":64,"z":10,"block":"minecraft:stone_bricks","region":"R3","texture":"textures/block/stone_bricks.png"},{"x":8,"y":64,"z":11,"block":"minecraft:stone_bricks","region":"R3","texture":"textures/block/stone_bricks.png"},{"x":8,"y":65,"z":5,"block":"minecraft:stone_bricks","region":"R2","texture":"textures/block/stone_bricks.png"},{"x":8,"y":65,"z":11,"block":"minecraft:stone_bricks","region":"R3","texture":"textures/block/stone_bricks.png"},{"x":8,"y":66,"z":5,"block":"minecraft:stone_bricks","region":"R2","texture":"textures/block/stone_bricks.png"},{"x":8,"y":66,"z":11,"block":"minecraft:glass_pane","region":"R3","texture":"textures/block/glass_pane.png"},{"x":8,"y":67,"z":5,"block":"minecraft:stone_bricks","region":"R2","texture":"textures/block/stone_bricks.png"},{"x":8,"y":67,"z":11,"block":"minecraft:stone_bricks","region":"R3","texture":"textures/block/stone_bricks.png"},{"x":8,"y":68,"z":0,"block":"minecraft:stone_bricks","region":"R2","texture":"textures/block/stone_bricks.png"},{"x":8,"y":68,"z":5,"block":"minecraft:glass_pane","region":"R2","texture":"textures/block/glass_pane.png"},{"x":8,"y":68,"z":11,"block":"minecraft:stone_bricks","region":"R3","texture":"textures/block/stone_bricks.png"},{"x":8,"y":69,"z":0,"block":"minecraft:stone_bricks","region":"R2","texture":"textures/block/stone_bricks.png"},{"x":8,"y":69,"z":5,"block":"minecraft:stone_bricks","region":"R2","texture":"textures/block/stone_bricks.png"},{"x":8,"y":69,"z":11,"block":"minecraft:stone_bricks","region":"R3","texture":"textures/block/stone_bricks.png"},{"x":8,"y":70,"z":0,"block":"minecraft:stone_bricks","region":"R2","texture":"textures/block/stone_bricks.png"},{"x":8,"y":70,"z":5,"block":"minecraft:stone_bricks","region":"R2","texture":"textures/block/stone_bricks.png"},{"x":8,"y":70,"z":11,"block":"minecraft:stone_bricks","region":"R3","texture":"textures/block/stone_bricks.png"},{"x":8,"y":71,"z":0,"block":"minecraft:stone_bricks","region":"R2","texture":"textures/block/stone_bricks.png"},{"x":8,"y":71,"z":1,"block":"minecraft:stone_bricks","region":"R2","texture":"textures/block/stone_bricks.png"},{"x":8,"y":71,"z":2,"block":"minecraft:stone_bricks","region":"R2","texture":"textures/block/stone_bricks.png"},{"x":8,"y":71,"z":3,"block":"minecraft:stone_bricks","region":"R2","texture":"textures/block/stone_bricks.png"},{"x":8,"y":71,"z":4,"block":"minecraft:stone_bricks","region":"R2","texture":"textures/block/stone_bricks.png"},{"x":8,"y":71,"z":5,"block":"minecraft:stone_bricks","region":"R2","texture":"textures/block/stone_bricks.png"},{"x":9,"y":64,"z":0,"block":"minecraft:stone_bricks","region":"R2","texture":"textures/block/stone_bricks.png"},{"x":9,"y":64,"z":1,"block":"minecraft:stone_bricks","region":"R2","texture":"textures/block/stone_bricks.png"},{"x":9,"y":64,"z":2,"block":"minecraft:stone_bricks","region":"R2","texture":"textures/block/stone_bricks.png"},{"x":9,"y":64,"z":3,"block":"minecraft:stone_bricks","region":"R2","texture":"textures/block/stone_bricks.png"},{"x":9,"y":64,"z":4,"block":"minecraft:stone_bricks","region":"R2","texture":"textures/block/stone_bricks.png"},{"x":9,"y":64,"z":5,"block":"minecraft:stone_bricks","region":"R2","texture":"textures/block/stone_bricks.png"},{"x":9,"y":64,"z":6,"block":"minecraft:stone_bricks","region":"R3","texture":"textures/block/stone_bricks.png"},{"x":9,"y":64,"z":7,"block":"minecraft:stone_bricks","region":"R3","texture":"textures/block/stone_bricks.png"},{"x":9,"y":64,"z":8,"block":"minecraft:stone_bricks","region":"R3","texture":"textures/block/stone_bricks.png"},{"x":9,"y":64,"z":9,"block":"minecraft:stone_bricks","region":"R3","texture":"textures/block/stone_bricks.png"},{"x":9,"y":64,"z":10,"block":"minecraft:stone_bricks","region":"R3","texture":"textures/block/stone_bricks.png"},{"x":9,"y":64,"z":11,"block":"minecraft:stone_bricks","region":"R3","texture":"textures/block/stone_bricks.png"},{"x":9,"y":65,"z":5,"block":"minecraft:stone_bricks","region":"R2","texture":"textures/block/stone_bricks.png"},{"x":9,"y":65,"z":11,"block":"minecraft:stone_bricks","region":"R3","texture":"textures/block/stone_bricks.png"},{"x":9,"y":66,"z":5,"block":"minecraft:stone_bricks","region":"R2","texture":"textures/block/stone_bricks.png"},{"x":9,"y":66,"z":11,"block":"minecraft:stone_bricks","region":"R3","texture":"textures/block/stone_bricks.png"},{"x":9,"y":67,"z":5,"block":"minecraft:stone_bricks","region":"R2","texture":"textures/block/stone_bricks.png"},{"x":9,"y":67,"z":11,"block":"minecraft:stone_bricks","region":"R3","texture":"textures/block/stone_bricks.png"},{"x":9,"y":68,"z":0,"block":"minecraft:stone_bricks","region":"R2","texture":"textures/block/stone_bricks.png"},{"x":9,"y":68,"z":5,"block":"minecraft:glass_pane","region":"R2","texture":"textures/block/glass_pane.png"},{"x":9,"y":68,"z":11,"block":"minecraft:stone_bricks","region":"R3","texture":"textures/block/stone_bricks.png"},{"x":9,"y":69,"z":0,"block":"minecraft:stone_bricks","region":"R2","texture":"textures/block/stone_bricks.png"},{"x":9,"y":69,"z":5,"block":"minecraft:stone_bricks","region":"R2","texture":"textures/block/stone_bricks.png"},{"x":9,"y":69,"z":11,"block":"minecraft:stone_bricks","region":"R3","texture":"textures/block/stone_bricks.png"},{"x":9,"y":70,"z":0,"block":"minecraft:stone_bricks","region":"R2","texture":"textures/block/stone_bricks.png"},{"x":9,"y":70,"z":5,"block":"minecraft:stone_bricks","region":"R2","texture":"textures/block/stone_bricks.png"},{"x":9,"y":70,"z":11,"block":"minecraft:stone_bricks","region":"R3","texture":"textures/block/stone_bricks.png"},{"x":9,"y":71,"z":0,"block":"minecraft:stone_bricks","region":"R2","texture":"textures/block/stone_bricks.png"},{"x":9,"y":71,"z":1,"block":"minecraft:stone_bricks","region":"R2","texture":"textures/block/stone_bricks.png"},{"x":9,"y":71,"z":2,"block":"minecraft:stone_bricks","region":"R2","texture":"textures/block/stone_bricks.png"},{"x":9,"y":71,"z":3,"block":"minecraft:stone_bricks","region":"R2","texture":"textures/block/stone_bricks.png"},{"x":9,"y":71,"z":4,"block":"minecraft:stone_bricks","region":"R2","texture":"textures/block/stone_bricks.png"},{"x":9,"y":71,"z":5,"block":"minecraft:stone_bricks","region":"R2","texture":"textures/block/stone_bricks.png"},{"x":10,"y":64,"z":0,"block":"minecraft:stone_bricks","region":"R2","texture":"textures/block/stone_bricks.png"},{"x":10,"y":64,"z":1,"block":"minecraft:stone_bricks","region":"R2","texture":"textures/block/stone_bricks.png"},{"x":10,"y":64,"z":2,"block":"minecraft:stone_bricks","region":"R2","texture":"textures/block/stone_bricks.png"},{"x":10,"y":64,"z":3,"block":"minecraft:stone_bricks","region":"R2","texture":"textures/block/stone_bricks.png"},{"x":10,"y":64,"z":4,"block":"minecraft:stone_bricks","region":"R2","texture":"textures/block/stone_bricks.png"},{"x":10,"y":64,"z":5,"block":"minecraft:stone_bricks","region":"R2","texture":"textures/block/stone_bricks.png"},{"x":10,"y":64,"z":6,"block":"minecraft:stone_bricks","region":"R3","texture":"textures/block/stone_bricks.png"},{"x":10,"y":64,"z":7,"block":"minecraft:stone_bricks","region":"R3","texture":"textures/block/stone_bricks.png"},{"x":10,"y":64,"z":8,"block":"minecraft:stone_bricks","region":"R3","texture":"textures/block/stone_bricks.png"},{"x":10,"y":64,"z":9,"block":"minecraft:stone_bricks","region":"R3","texture":"textures/block/stone_bricks.png"},{"x":10,"y":64,"z":10,"block":"minecraft:stone_bricks","region":"R3","texture":"textures/block/stone_bricks.png"},{"x":10,"y":64,"z":11,"block":"minecraft:stone_bricks","region":"R3","texture":"textures/block/stone_bricks.png"},{"x":10,"y":65,"z":0,"block":"minecraft:stone_bricks","region":"R2","texture":"textures/block/stone_bricks.png"},{"x":10,"y":65,"z":5,"block":"minecraft:stone_bricks","region":"R2","texture":"textures/block/stone_bricks.png"},{"x":10,"y":65,"z":11,"block":"minecraft:stone_bricks","region":"R3","texture":"textures/block/stone_bricks.png"},{"x":10,"y":66,"z":0,"block":"minecraft:stone_bricks","region":"R2","texture":"textures/block/stone_bricks.png"},{"x":10,"y":66,"z":5,"block":"minecraft:stone_bricks","region":"R2","texture":"textures/block/stone_bricks.png"},{"x":10,"y":66,"z":11,"block":"minecraft:stone_bricks","region":"R3","texture":"textures/block/stone_bricks.png"},{"x":10,"y":67,"z":0,"block":"minecraft:stone_bricks","region":"R2","texture":"textures/block/stone_bricks.png"},{"x":10,"y":67,"z":1,"block":"minecraft:lantern","region":"R2","texture":"textures/block/lantern.png"},{"x":10,"y":67,"z":5,"block":"minecraft:stone_bricks","region":"R2","texture":"textures/block/stone_bricks.png"},{"x":10,"y":67,"z":11,"block":"minecraft:stone_bricks","region":"R3","texture":"textures/block/stone_bricks.png"},{"x":10,"y":68,"z":0,"block":"minecraft:stone_bricks","region":"R2","texture":"textures/block/stone_bricks.png"},{"x":10,"y":68,"z":5,"block":"minecraft:stone_bricks","region":"R2","texture":"textures/block/stone_bricks.png"},{"x":10,"y":68,"z":11,"block":"minecraft:stone_bricks","region":"R3","texture":"textures/block/stone_bricks.png"},{"x":10,"y":69,"z":0,"block":"minecraft:stone_bricks","region":"R2","texture":"textures/block/stone_bricks.png"},{"x":10,"y":69,"z":5,"block":"minecraft:stone_bricks","region":"R2","texture":"textures/block/stone_bricks.png"},{"x":10,"y":69,"z":11,"block":"minecraft:stone_bricks","region":"R3","texture":"textures/block/stone_bricks.png"},{"x":10,"y":70,"z":0,"block":"minecraft:stone_bricks","region":"R2","texture":"textures/block/stone_bricks.png"},{"x":10,"y":70,"z":5,"block":"minecraft:stone_bricks","region":"R2","texture":"textures/block/stone_bricks.png"},{"x":10,"y":70,"z":11,"block":"minecraft:stone_bricks","region":"R3","texture":"textures/block/stone_bricks.png"},{"x":10,"y":71,"z":0,"block":"minecraft:stone_bricks","region":"R2","texture":"textures/block/stone_bricks.png"},{"x":10,"y":71,"z":1,"block":"minecraft:stone_bricks","region":"R2","texture":"textures/block/stone_bricks.png"},{"x":10,"y":71,"z":2,"block":"minecraft:stone_bricks","region":"R2","texture":"textures/block/stone_bricks.png"},{"x":10,"y":71,"z":3,"block":"minecraft:stone_bricks","region":"R2","texture":"textures/block/stone_bricks.png"},{"x":10,"y":71,"z":4,"block":"minecraft:stone_bricks","region":"R2","texture":"textures/block/stone_bricks.png"},{"x":10,"y":71,"z":5,"block":"minecraft:stone_bricks","region":"R2","texture":"textures/block/stone_bricks.png"},{"x":11,"y":64,"z":0,"block":"minecraft:stone_bricks","region":"R2","texture":"textures/block/stone_bricks.png"},{"x":11,"y":64,"z":1,"block":"minecraft:stone_bricks","region":"R2","texture":"textures/block/stone_bricks.png"},{"x":11,"y":64,"z":2,"block":"minecraft:stone_bricks","region":"R2","texture":"textures/block/stone_bricks.png"},{"x":11,"y":64,"z":3,"block":"minecraft:stone_bricks","region":"R2","texture":"textures/block/stone_bricks.png"},{"x":11,"y":64,"z":4,"block":"minecraft:stone_bricks","region":"R2","texture":"textures/block/stone_bricks.png"},{"x":11,"y":64,"z":5,"block":"minecraft:stone_bricks","region":"R2","texture":"textures/block/stone_bricks.png"},{"x":11,"y":64,"z":6,"block":"minecraft:stone_bricks","region":"R3","texture":"textures/block/stone_bricks.png"},{"x":11,"y":64,"z":7,"block":"minecraft:stone_bricks","region":"R3","texture":"textures/block/stone_bricks.png"},{"x":11,"y":64,"z":8,"block":"minecraft:stone_bricks","region":"R3","texture":"textures/block/stone_bricks.png"},{"x":11,"y":64,"z":9,"block":"minecraft:stone_bricks","region":"R3","texture":"textures/block/stone_bricks.png"},{"x":11,"y":64,"z":10,"block":"minecraft:stone_bricks","region":"R3","texture":"textures/block/stone_bricks.png"},{"x":11,"y":64,"z":11,"block":"minecraft:stone_bricks","region":"R3","texture":"textures/block/stone_bricks.png"},{"x":11,"y":65,"z":0,"block":"minecraft:stone_bricks","region":"R2","texture":"textures/block/stone_bricks.png"},{"x":11,"y":65,"z":1,"block":"minecraft:stone_bricks","region":"R2","texture":"textures/block/stone_bricks.png"},{"x":11,"y":65,"z":2,"block":"minecraft:stone_bricks","region":"R2","texture":"textures/block/stone_bricks.png"},{"x":11,"y":65,"z":3,"block":"minecraft:stone_bricks","region":"R2","texture":"textures/block/stone_bricks.png"},{"x":11,"y":65,"z":4,"block":"minecraft:stone_bricks","region":"R2","texture":"textures/block/stone_bricks.png"},{"x":11,"y":65,"z":5,"block":"minecraft:stone_bricks","region":"R2","texture":"textures/block/stone_bricks.png"},{"x":11,"y":65,"z":6,"block":"minecraft:stone_bricks","region":"R3","texture":"textures/block/stone_bricks.png"},{"x":11,"y":65,"z":7,"block":"minecraft:stone_bricks","region":"R3","texture":"textures/block/stone_bricks.png"},{"x":11,"y":65,"z":8,"block":"minecraft:stone_bricks","region":"R3","texture":"textures/block/stone_bricks.png"},{"x":11,"y":65,"z":9,"block":"minecraft:stone_bricks","region":"R3","texture":"textures/block/stone_bricks.png"},{"x":11,"y":65,"z":10,"block":"minecraft:stone_bricks","region":"R3","texture":"textures/block/stone_bricks.png"},{"x":11,"y":65,"z":11,"block":"minecraft:stone_bricks","region":"R3","texture":"textures/block/stone_bricks.png"},{"x":11,"y":66,"z":0,"block":"minecraft:stone_bricks","region":"R2","texture":"textures/block/stone_bricks.png"},{"x":11,"y":66,"z":1,"block":"minecraft:stone_bricks","region":"R2","texture":"textures/block/stone_bricks.png"},{"x":11,"y":66,"z":2,"block":"minecraft:stone_bricks","region":"R2","texture":"textures/block/stone_bricks.png"},{"x":11,"y":66,"z":3,"block":"minecraft:stone_bricks","region":"R2","texture":"textures/block/stone_bricks.png"},{"x":11,"y":66,"z":4,"block":"minecraft:stone_bricks","region":"R2","texture":"textures/block/stone_bricks.png"},{"x":11,"y":66,"z":5,"block":"minecraft:stone_bricks","region":"R2","texture":"textures/block/stone_bricks.png"},{"x":11,"y":66,"z":6,"block":"minecraft:stone_bricks","region":"R3","texture":"textures/block/stone_bricks.png"},{"x":11,"y":66,"z":7,"block":"minecraft:stone_bricks","region":"R3","texture":"textures/block/stone_bricks.png"},{"x":11,"y":66,"z":8,"block":"minecraft:stone_bricks","region":"R3","texture":"textures/block/stone_bricks.png"},{"x":11,"y":66,"z":9,"block":"minecraft:stone_bricks","region":"R3","texture":"textures/block/stone_bricks.png"},{"x":11,"y":66,"z":10,"block":"minecraft:stone_bricks","region":"R3","texture":"textures/block/stone_bricks.png"},{"x":11,"y":66,"z":11,"block":"minecraft:stone_bricks","region":"R3","texture":"textures/block/stone_bricks.png"},{"x":11,"y":67,"z":0,"block":"minecraft:stone_bricks","region":"R2","texture":"textures/block/stone_bricks.png"},{"x":11,"y":67,"z":1,"block":"minecraft:stone_bricks","region":"R2","texture":"textures/block/stone_bricks.png"},{"x":11,"y":67,"z":2,"block":"minecraft:stone_bricks","region":"R2","texture":"textures/block/stone_bricks.png"},{"x":11,"y":67,"z":3,"block":"minecraft:stone_bricks","region":"R2","texture":"textures/block/stone_bricks.png"},{"x":11,"y":67,"z":4,"block":"minecraft:stone_bricks","region":"R2","texture":"textures/block/stone_bricks.png"},{"x":11,"y":67,"z":5,"block":"minecraft:stone_bricks","region":"R2","texture":"textures/block/stone_bricks.png"},{"x":11,"y":67,"z":6,"block":"minecraft:stone_bricks","region":"R3","texture":"textures/block/stone_bricks.png"},{"x":11,"y":67,"z":7,"block":"minecraft:stone_bricks","region":"R3","texture":"textures/block/stone_bricks.png"},{"x":11,"y":67,"z":8,"block":"minecraft:stone_bricks","region":"R3","texture":"textures/block/stone_bricks.png"},{"x":11,"y":67,"z":9,"block":"minecraft:stone_bricks","region":"R3","texture":"textures/block/stone_bricks.png"},{"x":11,"y":67,"z":10,"block":"minecraft:stone_bricks","region":"R3","texture":"textures/block/stone_bricks.png"},{"x":11,"y":67,"z":11,"block":"minecraft:stone_bricks","region":"R3","texture":"textures/block/stone_bricks.png"},{"x":11,"y":68,"z":0,"block":"minecraft:stone_bricks","region":"R2","texture":"textures/block/stone_bricks.png"},{"x":11,"y":68,"z":1,"block":"minecraft:stone_bricks","region":"R2","texture":"textures/block/stone_bricks.png"},{"x":11,"y":68,"z":2,"block":"minecraft:stone_bricks","region":"R2","texture":"textures/block/stone_bricks.png"},{"x":11,"y":68,"z":3,"block":"minecraft:stone_bricks","region":"R2","texture":"textures/block/stone_bricks.png"},{"x":11,"y":68,"z":4,"block":"minecraft:stone_bricks","region":"R2","texture":"textures/block/stone_bricks.png"},{"x":11,"y":68,"z":5,"block":"minecraft:stone_bricks","region":"R2","texture":"textures/block/stone_bricks.png"},{"x":11,"y":68,"z":6,"block":"minecraft:stone_bricks","region":"R3","texture":"textures/block/stone_bricks.png"},{"x":11,"y":68,"z":7,"block":"minecraft:stone_bricks","region":"R3","texture":"textures/block/stone_bricks.png"},{"x":11,"y":68,"z":8,"block":"minecraft:stone_bricks","region":"R3","texture":"textures/block/stone_bricks.png"},{"x":11,"y":68,"z":9,"block":"minecraft:stone_bricks","region":"R3","texture":"textures/block/stone_bricks.png"},{"x":11,"y":68,"z":10,"block":"minecraft:stone_bricks","region":"R3","texture":"textures/block/stone_bricks.png"},{"x":11,"y":68,"z":11,"block":"minecraft:stone_bricks","region":"R3","texture":"textures/block/stone_bricks.png"},{"x":11,"y":69,"z":0,"block":"minecraft:stone_bricks","region":"R2","texture":"textures/block/stone_bricks.png"},{"x":11,"y":69,"z":1,"block":"minecraft:stone_bricks","region":"R2","texture":"textures/block/stone_bricks.png"},{"x":11,"y":69,"z":2,"block":"minecraft:stone_bricks","region":"R2","texture":"textures/block/stone_bricks.png"},{"x":11,"y":69,"z":3,"block":"minecraft:stone_bricks","region":"R2","texture":"textures/block/stone_bricks.png"},{"x":11,"y":69,"z":4,"block":"minecraft:stone_bricks","region":"R2","texture":"textures/block/stone_bricks.png"},{"x":11,"y":69,"z":5,"block":"minecraft:stone_bricks","region":"R2","texture":"textures/block/stone_bricks.png"},{"x":11,"y":69,"z":6,"block":"minecraft:stone_bricks","region":"R3","texture":"textures/block/stone_bricks.png"},{"x":11,"y":69,"z":7,"block":"minecraft:stone_bricks","region":"R3","texture":"textures/block/stone_bricks.png"},{"x":11,"y":69,"z":8,"block":"minecraft:stone_bricks","region":"R3","texture":"textures/block/stone_bricks.png"},{"x":11,"y":69,"z":9,"block":"minecraft:stone_bricks","region":"R3","texture":"textures/block/stone_bricks.png"},{"x":11,"y":69,"z":10,"block":"minecraft:stone_bricks","region":"R3","texture":"textures/block/stone_bricks.png"},{"x":11,"y":69,"z":11,"block":"minecraft:stone_bricks","region":"R3","texture":"textures/block/stone_bricks.png"},{"x":11,"y":70,"z":0,"block":"minecraft:stone_bricks","region":"R2","texture":"textures/block/stone_bricks.png"},{"x":11,"y":70,"z":1,"block":"minecraft:stone_bricks","region":"R2","texture":"textures/block/stone_bricks.png"},{"x":11,"y":70,"z":2,"block":"minecraft:stone_bricks","region":"R2","texture":"textures/block/stone_bricks.png"},{"x":11,"y":70,"z":3,"block":"minecraft:stone_bricks","region":"R2","texture":"textures/block/stone_bricks.png"},{"x":11,"y":70,"z":4,"block":"minecraft:stone_bricks","region":"R2","texture":"textures/block/stone_bricks.png"},{"x":11,"y":70,"z":5,"block":"minecraft:stone_bricks","region":"R2","texture":"textures/block/stone_bricks.png"},{"x":11,"y":70,"z":11,"block":"minecraft:stone_bricks","region":"R3","texture":"textures/block/stone_bricks.png"},{"x":11,"y":71,"z":0,"block":"minecraft:stone_bricks","region":"R2","texture":"textures/block/stone_bricks.png"},{"x":11,"y":71,"z":1,"block":"minecraft:stone_bricks","region":"R2","texture":"textures/block/stone_bricks.png"},{"x":11,"y":71,"z":2,"block":"minecraft:stone_bricks","region":"R2","texture":"textures/block/stone_bricks.png"},{"x":11,"y":71,"z":3,"block":"minecraft:stone_bricks","region":"R2","texture":"textures/block/stone_bricks.png"},{"x":11,"y":71,"z":4,"block":"minecraft:stone_bricks","region":"R2","texture":"textures/block/stone_bricks.png"},{"x":11,"y":71,"z":5,"block":"minecraft:stone_bricks","region":"R2","texture":"textures/block/stone_bricks.png"}],"regions":[{"id":"R1","box":[0,0,0,5,7,5],"role":"northwest_tower","constraints":[]},{"id":"R2","box":[6,0,0,11,7,5],"role":"north_gate_wall","constraints":[]},{"id":"R3","box":[0,0,6,11,7,11],"role":"courtyard_and_south_wall","constraints":[]}],"interfaces":[{"id":"R1_R2_wall_connection","between":["R1","R2"],"type":"wall_connection","position":{"x":6,"y":[0,3],"z":2},"rule":"Walls must connect without gaps."},{"id":"R2_R3_main_gate","between":["R2","R3"],"type":"main_gate","position":{"x":[8,9],"y":[1,3],"z":6},"rule":"Gate opening must stay clear above the floor."}],"errors":[]}}